<?xml version="1.0" encoding="utf-8"?>
<!-- This URDF was automatically created by SolidWorks to URDF Exporter! Originally created by Stephen Brawner (brawner@gmail.com) 
     Commit Version: 1.6.0-4-g7f85cfe  Build Version: 1.6.7995.38578
     For more information, please see http://wiki.ros.org/sw_urdf_exporter -->
<robot
  name="wheelchair_gp_description2">
    <origin xyz="0 0 0.37687875"
        rpy="0 0 0" />
  <link
    name="base_link">
    <inertial>
      <!--origin
        xyz="-0.0397576730779188 -0.0193564999839691 -0.0391654560144318"
        rpy="0 0 0" /-->
      <origin
        xyz="-0.0397576730779188 -0.0193564999839691 -0.0391654560144318"
        rpy="0 0 0" />
      <mass
        value="102.867303195028" />
      
      <!--inertia
        ixx="2.4436126563851"
        ixy="0.00330590044188402"
        ixz="0.167289560017964"
        iyy="3.43143183338679"
        iyz="0.0623789722811827"
        izz="3.64685457880825" /-->
        <inertia
        ixx="0.4436126563851"
        ixy="0.00330590044188402"
        ixz="0.167289560017964"
        iyy="0.43143183338679"
        iyz="0.0623789722811827"
        izz="0.64685457880825" />
    </inertial>
    <visual>
      <origin
        xyz="0 0 0"
        rpy="0 0 0" />
      <geometry>
        <mesh
          filename="package://wheelchair_gp_description2/meshes/base_link.STL" />
      </geometry>
      <material
        name="">
        <color
          rgba="0.647058823529412 0.619607843137255 0.588235294117647 1" />
      </material>
    </visual>
    <collision>
      <origin
        xyz="0 0 0"
        rpy="0 0 0" />
      <geometry>
        <mesh
          filename="package://wheelchair_gp_description2/meshes/base_link.STL" />
      </geometry>
    </collision>
  </link>
  <link
    name="right_wheel_link">
    <inertial>
      <origin
        xyz="0.0051016277034862 -0.030000000000002 -0.00883712628242247"
        rpy="0 0 0" />
      <mass
        value="3.63792559240615" />
      <inertia
        ixx="0.0501393580967394"
        ixy="-1.08357299378418E-19"
        ixz="-8.37248749194007E-07"
        iyy="0.0986432390550648"
        iyz="1.67436686126197E-16"
        izz="0.0501416739249588" />
    </inertial>
    <visual>
      <origin
        xyz="0 0 0"
        rpy="0 0 0" />
      <geometry>
        <mesh
          filename="package://wheelchair_gp_description2/meshes/right_wheel_link.STL" />
      </geometry>
      <material
        name="">
        <color
          rgba="0.792156862745098 0.819607843137255 0.933333333333333 1" />
      </material>
    </visual>
    <collision>
      <origin
        xyz="0 0 0"
        rpy="0 0 0" />
      <geometry>
        <mesh
          filename="package://wheelchair_gp_description2/meshes/right_wheel_link.STL" />
      </geometry>
    </collision>
  </link>
  <joint
    name="right_wheel_joint"
    type="continuous">
    <origin
      xyz="-0.0782370331711224 -0.291972990052419 -0.168374239027783"
      rpy="0 0 0" />
    <parent
      link="base_link" />
    <child
      link="right_wheel_link" />
    <axis
      xyz="0 1 0" />
    <dynamics
      damping="0"
      friction="0.2" />
  </joint>
  <link
    name="left_wheel_link">
    <inertial>
      <origin
        xyz="0.00019641498461731 0.0300000000000018 -7.01814500627673E-05"
        rpy="0 0 0" />
      <mass
        value="3.63792559240615" />
      <inertia
        ixx="0.0501416166910778"
        ixy="-4.04451943510893E-18"
        ixz="-9.11182521543606E-07"
        iyy="0.0986432390550647"
        iyz="1.94384109555964E-16"
        izz="0.0501394153306204" />
    </inertial>
    <visual>
      <origin
        xyz="0 0 0"
        rpy="0 0 0" />
      <geometry>
        <mesh
          filename="package://wheelchair_gp_description2/meshes/left_wheel_link.STL" />
      </geometry>
      <material
        name="">
        <color
          rgba="0.792156862745098 0.819607843137255 0.933333333333333 1" />
      </material>
    </visual>
    <collision>
      <origin
        xyz="0 0 0"
        rpy="0 0 0" />
      <geometry>
        <mesh
          filename="package://wheelchair_gp_description2/meshes/left_wheel_link.STL" />
      </geometry>
    </collision>
  </link>
  <joint
    name="left_wheel_joint"
    type="continuous">
    <origin
      xyz="-0.0732 0.27496 -0.17701"
      rpy="0 0 0" />
    <parent
      link="base_link" />
    <child
      link="left_wheel_link" />
    <axis
      xyz="0 1 0" />
    <dynamics
      damping="0"
      friction="0.2" />
  </joint>
  <link
    name="c_rr_link">
    <inertial>
      <origin
        xyz="-0.0451841547006857 -0.0495150883715779 0.0403769854454999"
        rpy="0 0 0" />
      <mass
        value="0.121211258399187" />
      <inertia
        ixx="0.000183879326955444"
        ixy="2.26483161983074E-11"
        ixz="-3.32770031866735E-12"
        iyy="0.000178527913603531"
        iyz="-2.16822895135042E-05"
        izz="2.37333780216088E-05" />
    </inertial>
    <visual>
      <origin
        xyz="0 0 0"
        rpy="0 0 0" />
      <geometry>
        <mesh
          filename="package://wheelchair_gp_description2/meshes/c_rr_link.STL" />
      </geometry>
      <material
        name="">
        <color
          rgba="1 1 1 1" />
      </material>
    </visual>
    <collision>
      <origin
        xyz="0 0 0"
        rpy="0 0 0" />
      <geometry>
        <mesh
          filename="package://wheelchair_gp_description2/meshes/c_rr_link.STL" />
      </geometry>
    </collision>
  </link>
  <joint
    name="c_rr_joint"
    type="fixed">
    <origin
      xyz="-0.34822 -0.32107 -0.27701"
      rpy="0 0 0" />
    <parent
      link="base_link" />
    <child
      link="c_rr_link" />
    <axis
      xyz="0 0 1" />
    <dynamics
      damping="0"
      friction="0.01" />
  </joint>
  <link
    name="wheel_rr_link">
    <inertial>
      <origin
        xyz="-0.0401191911455145 -0.0782732802971556 0.00862243945121771"
        rpy="0 0 0" />
      <mass
        value="1.6546211917139" />
      <inertia
        ixx="0.00469812484295985"
        ixy="3.0986980923837E-10"
        ixz="2.19470322426369E-19"
        iyy="0.00853457249449096"
        iyz="-1.1422522877663E-10"
        izz="0.00469812484295985" />
    </inertial>
    <visual>
      <origin
        xyz="0 0 0"
        rpy="0 0 0" />
      <geometry>
        <mesh
          filename="package://wheelchair_gp_description2/meshes/wheel_rr_link.STL" />
      </geometry>
      <material
        name="">
        <color
          rgba="0.666666666666667 0.698039215686274 0.768627450980392 1" />
      </material>
    </visual>
    <collision>
      <origin
        xyz="0 0 0"
        rpy="0 0 0" />
      <geometry>
        <mesh
          filename="package://wheelchair_gp_description2/meshes/wheel_rr_link.STL" />
      </geometry>
    </collision>
  </link>
  <joint
    name="wheel_rr_joint"
    type="continuous">
    <origin
      xyz="-0.0050649 -0.026911 -0.0086224"
      rpy="0 0 0" />
    <parent
      link="c_rr_link" />
    <child
      link="wheel_rr_link" />
    <axis
      xyz="0 1 0" />
    <dynamics
      damping="0"
      friction="0.01" />
  </joint>
  <link
    name="c_rl_link">
    <inertial>
      <origin
        xyz="-0.0310419563112246 0.0352158260013177 0.0403769854454989"
        rpy="0 0 0" />
      <mass
        value="0.121211258399187" />
      <inertia
        ixx="0.000183879326955444"
        ixy="2.26483161950639E-11"
        ixz="3.32770035496429E-12"
        iyy="0.000178527913603531"
        iyz="2.16822895135046E-05"
        izz="2.37333780216089E-05" />
    </inertial>
    <visual>
      <origin
        xyz="0 0 0"
        rpy="0 0 0" />
      <geometry>
        <mesh
          filename="package://wheelchair_gp_description2/meshes/c_rl_link.STL" />
      </geometry>
      <material
        name="">
        <color
          rgba="1 1 1 1" />
      </material>
    </visual>
    <collision>
      <origin
        xyz="0 0 0"
        rpy="0 0 0" />
      <geometry>
        <mesh
          filename="package://wheelchair_gp_description2/meshes/c_rl_link.STL" />
      </geometry>
    </collision>
  </link>
  <joint
    name="c_rl_joint"
    type="fixed">
    <origin
      xyz="-0.3413 0.30405 -0.27701"
      rpy="0 0 0" />
    <parent
      link="base_link" />
    <child
      link="c_rl_link" />
    <axis
      xyz="0 0 1" />
    <dynamics
      damping="0"
      friction="0.01" />
  </joint>
  <link
    name="wheel_rl_link">
    <inertial>
      <origin
        xyz="-0.0219456935418381 0.0639740179268966 -0.00415420662650179"
        rpy="0 0 0" />
      <mass
        value="1.65462119171389" />
      <inertia
        ixx="0.0046981248429598"
        ixy="-1.37193710697476E-10"
        ixz="-1.71973499121677E-19"
        iyy="0.00853457249449089"
        iyz="-3.00407370003487E-10"
        izz="0.0046981248429598" />
    </inertial>
    <visual>
      <origin
        xyz="0 0 0"
        rpy="0 0 0" />
      <geometry>
        <mesh
          filename="package://wheelchair_gp_description2/meshes/wheel_rl_link.STL" />
      </geometry>
      <material
        name="">
        <color
          rgba="0.666666666666667 0.698039215686274 0.768627450980392 1" />
      </material>
    </visual>
    <collision>
      <origin
        xyz="0 0 0"
        rpy="0 0 0" />
      <geometry>
        <mesh
          filename="package://wheelchair_gp_description2/meshes/wheel_rl_link.STL" />
      </geometry>
    </collision>
  </link>
  <joint
    name="wheel_rl_joint"
    type="continuous">
    <origin
      xyz="-0.0090963 0.026911 0.0041542"
      rpy="0 0 0" />
    <parent
      link="c_rl_link" />
    <child
      link="wheel_rl_link" />
    <axis
      xyz="0 1 0" />
    <dynamics
      damping="0"
      friction="0.01" />
  </joint>
  <link
    name="c_fl_link">
    <inertial>
      <origin
        xyz="3.13828648068615E-08 0.00433096505375724 0.0403769854455023"
        rpy="0 0 0" />
      <mass
        value="0.121211258399187" />
      <inertia
        ixx="0.000183879326955444"
        ixy="2.26483161946498E-11"
        ixz="3.3277003851598E-12"
        iyy="0.000178527913603531"
        iyz="2.16822895135046E-05"
        izz="2.37333780216089E-05" />
    </inertial>
    <visual>
      <origin
        xyz="0 0 0"
        rpy="0 0 0" />
      <geometry>
        <mesh
          filename="package://wheelchair_gp_description2/meshes/c_fl_link.STL" />
      </geometry>
      <material
        name="">
        <color
          rgba="1 1 1 1" />
      </material>
    </visual>
    <collision>
      <origin
        xyz="0 0 0"
        rpy="0 0 0" />
      <geometry>
        <mesh
          filename="package://wheelchair_gp_description2/meshes/c_fl_link.STL" />
      </geometry>
    </collision>
  </link>
  <joint
    name="c_fl_joint"
    type="fixed">
    <origin
      xyz="0.27689 0.30405 -0.27701"
      rpy="0 0 0" />
    <parent
      link="base_link" />
    <child
      link="c_fl_link" />
    <axis
      xyz="0 0 1" />
    <dynamics
      damping="0"
      friction="0.01" />
  </joint>
  <link
    name="wheel_fl_link">
    <inertial>
      <origin
        xyz="0.00446139900539494 0.0330891569793361 -0.00894963233404278"
        rpy="0 0 0" />
      <mass
        value="1.65462119171389" />
      <inertia
        ixx="0.00469812484295982"
        ixy="-3.28553669286032E-10"
        ixz="1.63655263306549E-18"
        iyy="0.0085345724944909"
        iyz="-3.34543045495122E-11"
        izz="0.00469812484295982" />
    </inertial>
    <visual>
      <origin
        xyz="0 0 0"
        rpy="0 0 0" />
      <geometry>
        <mesh
          filename="package://wheelchair_gp_description2/meshes/wheel_fl_link.STL" />
      </geometry>
      <material
        name="">
        <color
          rgba="0.666666666666667 0.698039215686274 0.768627450980392 1" />
      </material>
    </visual>
    <collision>
      <origin
        xyz="0 0 0"
        rpy="0 0 0" />
      <geometry>
        <mesh
          filename="package://wheelchair_gp_description2/meshes/wheel_fl_link.STL" />
      </geometry>
    </collision>
  </link>
  <joint
    name="wheel_fl_joint"
    type="continuous">
    <origin
      xyz="-0.0044614 0.026911 0.0089496"
      rpy="0 0 0" />
    <parent
      link="c_fl_link" />
    <child
      link="wheel_fl_link" />
    <axis
      xyz="0 -1 0" />
    <dynamics
      damping="0"
      friction="0.01" />
  </joint>
  <link
    name="c_fr_link">
    <inertial>
      <origin
        xyz="-3.13828649178838E-08 -0.00433096505375735 0.0403769854454989"
        rpy="0 0 0" />
      <mass
        value="0.121211258399187" />
      <inertia
        ixx="0.000183879326955444"
        ixy="2.26483162486997E-11"
        ixz="-3.32769997600903E-12"
        iyy="0.000178527913603531"
        iyz="-2.16822895135042E-05"
        izz="2.37333780216088E-05" />
    </inertial>
    <visual>
      <origin
        xyz="0 0 0"
        rpy="0 0 0" />
      <geometry>
        <mesh
          filename="package://wheelchair_gp_description2/meshes/c_fr_link.STL" />
      </geometry>
      <material
        name="">
        <color
          rgba="1 1 1 1" />
      </material>
    </visual>
    <collision>
      <origin
        xyz="0 0 0"
        rpy="0 0 0" />
      <geometry>
        <mesh
          filename="package://wheelchair_gp_description2/meshes/c_fr_link.STL" />
      </geometry>
    </collision>
  </link>
  <joint
    name="c_fr_joint"
    type="fixed">
    <origin
      xyz="0.28382 -0.32107 -0.27701"
      rpy="0 0 0" />
    <parent
      link="base_link" />
    <child
      link="c_fr_link" />
    <axis
      xyz="0 0 1" />
    <dynamics
      damping="0"
      friction="0.01" />
  </joint>
  <link
    name="wheel_fr_link">
    <inertial>
      <origin
        xyz="5.55111512312578E-17 -0.05 1.66533453693773E-16"
        rpy="0 0 0" />
      <mass
        value="1.65462119171388" />
      <inertia
        ixx="0.0046981248429598"
        ixy="-6.92222670806783E-11"
        ixz="3.44437219170415E-19"
        iyy="0.00853457249449086"
        iyz="-3.2291635961725E-10"
        izz="0.0046981248429598" />
    </inertial>
    <visual>
      <origin
        xyz="0 0 0"
        rpy="0 0 0" />
      <geometry>
        <mesh
          filename="package://wheelchair_gp_description2/meshes/wheel_fr_link.STL" />
      </geometry>
      <material
        name="">
        <color
          rgba="0.666666666666667 0.698039215686274 0.768627450980392 1" />
      </material>
    </visual>
    <collision>
      <origin
        xyz="0 0 0"
        rpy="0 0 0" />
      <geometry>
        <mesh
          filename="package://wheelchair_gp_description2/meshes/wheel_fr_link.STL" />
      </geometry>
    </collision>
  </link>
  <joint
    name="wheel_fr_joint"
    type="continuous">
    <origin
      xyz="0 -0.01 0"
      rpy="0 0 0" />
    <parent
      link="c_fr_link" />
    <child
      link="wheel_fr_link" />
    <axis
      xyz="0 1 0" />
    <dynamics
      damping="0"
      friction="0.01" />
  </joint>
  <link
    name="chair_link">
    <inertial>
      <origin
        xyz="-0.186634259898291 0.000154601290753766 0.685315360247557"
        rpy="0 0 0" />
      <mass
        value="114.06700966343" />
      <inertia
        ixx="9.01362340563564"
        ixy="0.0220781525155632"
        ixz="2.75872047758239"
        iyy="10.1495034165686"
        iyz="0.0794043830621217"
        izz="6.74522524259257" />
    </inertial>
    <visual>
      <origin
        xyz="0 0 0"
        rpy="0 0 0" />
      <geometry>
        <mesh
          filename="package://wheelchair_gp_description2/meshes/chair_link.STL" />
      </geometry>
      <material
        name="">
        <color
          rgba="1 1 1 0.3" />
      </material>
    </visual>
    <collision>
      <origin
        xyz="0 0 0"
        rpy="0 0 0" />
      <geometry>
        <mesh
          filename="package://wheelchair_gp_description2/meshes/chair_link.STL" />
      </geometry>
    </collision>
  </link>
  <joint
    name="chair_joint"
    type="fixed">
    <origin
      xyz="0.085065 -0.021973 -0.21301"
      rpy="0 0 0" />
    <parent
      link="base_link" />
    <child
      link="chair_link" />
    <axis
      xyz="0 0 0" />
    <dynamics
      damping="0"
      friction="0" />
  </joint>
  <link
    name="laser_link">
    <inertial>
      <origin
        xyz="0.000495122459176101 0.0164439641378342 0.00393830970343467"
        rpy="0 0 0" />
      <mass
        value="0.171593009361433" />
      <inertia
        ixx="8.81695539048464E-05"
        ixy="1.02435205100894E-06"
        ixz="-2.45142607227697E-07"
        iyy="5.55321136136403E-05"
        iyz="-4.34621326843885E-06"
        izz="0.000129552246180809" />
    </inertial>
    <visual>
      <origin
        xyz="0 0 0"
        rpy="0 0 0" />
      <geometry>
        <mesh
          filename="package://wheelchair_gp_description2/meshes/laser_link.STL" />
      </geometry>
      <material
        name="">
        <color
          rgba="1 1 1 0.3" />
      </material>
    </visual>
    <collision>
      <origin
        xyz="0 0 0"
        rpy="0 0 0" />
      <geometry>
        <mesh
          filename="package://wheelchair_gp_description2/meshes/laser_link.STL" />
      </geometry>
    </collision>
  </link>
  <joint
    name="laser_joint"
    type="fixed">
    <origin
      xyz="-0.37477 0 1.625"
      rpy="0 0 0" />
    <parent
      link="chair_link" />
    <child
      link="laser_link" />
    <axis
      xyz="0 0 0" />
    <dynamics
      damping="0"
      friction="0" />
  </joint>
  <link
    name="imu_link">
    <inertial>
      <origin
        xyz="0.0189494667461579 0.005 -0.0105210784313726"
        rpy="0 0 0" />
      <mass
        value="0.00813424809545575" />
      <inertia
        ixx="3.67920423318068E-07"
        ixy="-1.30116975520072E-21"
        ixz="1.20843471589941E-21"
        iyy="1.27375650027243E-06"
        iyz="-2.03230716110828E-22"
        izz="1.04140687854529E-06" />
    </inertial>
    <visual>
      <origin
        xyz="0 0 0"
        rpy="0 0 0" />
      <geometry>
        <mesh
          filename="package://wheelchair_gp_description2/meshes/imu_link.STL" />
      </geometry>
      <material
        name="">
        <color
          rgba="1 1 1 1" />
      </material>
    </visual>
    <collision>
      <origin
        xyz="0 0 0"
        rpy="0 0 0" />
      <geometry>
        <mesh
          filename="package://wheelchair_gp_description2/meshes/imu_link.STL" />
      </geometry>
    </collision>
  </link>
  <joint
    name="imu_joint"
    type="fixed">
    <origin
      xyz="0.1569 0.073915 0.13699"
      rpy="1.5708 0 0" />
    <parent
      link="base_link" />
    <child
      link="imu_link" />
    <axis
      xyz="0 0 0" />
    <dynamics
      damping="0"
      friction="0" />
  </joint>
  <link
    name="sonar1_link">
    <inertial>
      <origin
        xyz="0.03 0.00999999999999999 0.0125"
        rpy="0 0 0" />
      <mass
        value="0.0260730091830128" />
      <inertia
        ixx="2.33342553567574E-06"
        ixy="-1.26877688189507E-23"
        ixz="4.34454885446642E-21"
        iyy="8.76262920888083E-06"
        iyz="-1.33823752473871E-22"
        izz="8.38011628799275E-06" />
    </inertial>
    <visual>
      <origin
        xyz="0 0 0"
        rpy="0 0 0" />
      <geometry>
        <mesh
          filename="package://wheelchair_gp_description2/meshes/sonar1_link.STL" />
      </geometry>
      <material
        name="">
        <color
          rgba="0.792156862745098 0.819607843137255 0.933333333333333 1" />
      </material>
    </visual>
    <collision>
      <origin
        xyz="0 0 0"
        rpy="0 0 0" />
      <geometry>
        <mesh
          filename="package://wheelchair_gp_description2/meshes/sonar1_link.STL" />
      </geometry>
    </collision>
  </link>
  <joint
    name="sonar1_frame"
    type="fixed">
    <origin
      xyz="0.2097 -0.27197 0.021202"
      rpy="1.5708 0 -0.5" />
    <parent
      link="base_link" />
    <child
      link="sonar1_link" />
    <axis
      xyz="0 0 0" />
  </joint>
  <link
    name="sonar2_link">
    <inertial>
      <origin
        xyz="-0.0259807621135068 0.00999999999999991 0.0125000000000001"
        rpy="0 0 0" />
      <mass
        value="0.0260730091830128" />
      <inertia
        ixx="2.33342553567575E-06"
        ixy="-2.34429122028608E-20"
        ixz="5.34689547954273E-21"
        iyy="8.76262920888086E-06"
        iyz="-1.09041038000863E-22"
        izz="8.38011628799277E-06" />
    </inertial>
    <visual>
      <origin
        xyz="0 0 0"
        rpy="0 0 0" />
      <geometry>
        <mesh
          filename="package://wheelchair_gp_description2/meshes/sonar2_link.STL" />
      </geometry>
      <material
        name="">
        <color
          rgba="0.792156862745098 0.819607843137255 0.933333333333333 1" />
      </material>
    </visual>
    <collision>
      <origin
        xyz="0 0 0"
        rpy="0 0 0" />
      <geometry>
        <mesh
          filename="package://wheelchair_gp_description2/meshes/sonar2_link.STL" />
      </geometry>
    </collision>
  </link>
  <joint
    name="sonar2_frame"
    type="fixed">
    <origin
      xyz="0.2037 -0.21461 -0.0087977"
      rpy="1.5708 0 0" />
    <parent
      link="base_link" />
    <child
      link="sonar2_link" />
    <axis
      xyz="1 0 0" />
  </joint>
  
  
  
  
   <gazebo reference="imu_link">
    <gravity>true</gravity>
    <sensor name="imu_sensor" type="imu">
      <always_on>true</always_on>
      <update_rate>100</update_rate>
      <visualize>true</visualize>
      <topic>__default_topic__</topic>
      <plugin filename="libgazebo_ros_imu_sensor.so" name="imu_plugin">
        <topicName>imu</topicName>
        <bodyName>imu_link</bodyName>
        <updateRateHZ>10.0</updateRateHZ>
        <gaussianNoise>0.0</gaussianNoise>
        <xyzOffset>0 0 0</xyzOffset>
        <rpyOffset>0 0 0</rpyOffset>
        <frameName>imu_link</frameName>
        <initialOrientationAsReference>false</initialOrientationAsReference>
      </plugin>
      <pose>0 0 0 0 0 0</pose>
    </sensor>
  </gazebo>
  
  
    
  
  

<gazebo reference="right_wheel_link">
<material>Gazebo/Black</material>
</gazebo>	

<gazebo reference="left_wheel_link">

<material>Gazebo/Black</material>
</gazebo>

<gazebo reference="wheel_rl_link">

<material>Gazebo/Blue</material>
</gazebo>	

<gazebo reference="wheel_rr_link">

<material>Gazebo/Blue</material>
</gazebo>



<gazebo reference="wheel_fr_link">

<material>Gazebo/Blue</material>
</gazebo>	

<gazebo reference="wheel_fl_link">

<material>Gazebo/Blue</material>
</gazebo>



<gazebo reference="base_link">

<material>Gazebo/Silver</material>
</gazebo>



<gazebo reference="chair_link">

<material>Gazebo/Red</material>
</gazebo>



<gazebo reference="laser_link">

<material>Gazebo/Green</material>
</gazebo>


  <!-- hokuyo -->
  <gazebo reference="laser_link">
    <sensor type="ray" name="head_hokuyo_sensor">
      <pose>0 0 0 0 0 0</pose>
      <visualize>true</visualize>
      <update_rate>40</update_rate>
      <ray>
        <scan>
          <horizontal>
            <samples>1024</samples>
            <resolution>1</resolution>
            <min_angle>-3.14</min_angle>
            <max_angle>3.14</max_angle>
          </horizontal>
        </scan>
        <range>
          <min>0.10</min>
          <max>30.0</max>
          <resolution>0.01</resolution>
        </range>
        <noise>
          <type>gaussian</type>
          <!-- Noise parameters based on published spec for Hokuyo laser
               achieving "+-30mm" accuracy at range < 10m.  A mean of 0.0m and
               stddev of 0.01m will put 99.7% of samples within 0.03m of the true
               reading. -->
          <mean>0.0</mean>
          <stddev>0.01</stddev>
        </noise>
      </ray>
      <plugin name="gazebo_ros_head_hokuyo_controller" filename="libgazebo_ros_laser.so">
        <topicName>/scan</topicName>
        <frameName>laser_link</frameName>
      </plugin>
    </sensor>
  </gazebo>



 
  <gazebo>
  <plugin name="differential_drive_controller" filename="libgazebo_ros_diff_drive.so">
    <alwaysOn>true</alwaysOn>
    <legacyMode>false</legacyMode>
    <updateRate>40</updateRate>
    <leftJoint>left_wheel_joint</leftJoint>
    <rightJoint>right_wheel_joint</rightJoint>
    <wheelSeparation>0.6</wheelSeparation>
    <wheelDiameter>0.3</wheelDiameter>
    <torque>250</torque>
    <wheelTorque>250</wheelTorque>
    <commandTopic>cmd_vel</commandTopic>
    <odometryTopic>odom</odometryTopic>
    <odometryFrame>odom</odometryFrame>
    <robotBaseFrame>base_link</robotBaseFrame>
  </plugin>
</gazebo>


<gazebo reference="sonar1_link">        
   <sensor type="ray" name="ultrasonic_1">
      <pose>0 0 0 0 0 0</pose>
      <visualize>true</visualize>
      <update_rate>50</update_rate>
      <ray>
         <scan>
            <horizontal>
               <samples>10</samples>
               <resolution>1</resolution> 
               <!--min_angle>-0.14835</min_angle>
               <max_angle>0.14835</max_angle-->
               <min_angle>-0.001</min_angle>
               <max_angle>0.001</max_angle>
            </horizontal>
            <vertical>
               <samples>10</samples>
               <resolution>1</resolution> 
               <min_angle>-0.001</min_angle>
               <max_angle>0.001</max_angle> 
            </vertical>
         </scan>
         <range>
            <min>0.01</min>
            <max>4</max>
            <resolution>0.02</resolution>
         </range>
      </ray>
      <plugin filename="libgazebo_ros_range.so" name="gazebo_ros_range">
         <gaussianNoise>0.005</gaussianNoise>
         <alwaysOn>true</alwaysOn>
         <updateRate>50</updateRate>
         <topicName>sonars/sonar1</topicName>
         <frameName>sonar1_link</frameName>
         <radiation>ULTRASOUND</radiation>
         <fov>0.2967</fov>
      </plugin>
   </sensor>  
   </gazebo>
   
   
<gazebo reference="sonar2_link">        
   <sensor type="ray" name="ultrasonic_2">
      <pose>0 0 0 0 0 0</pose>
      <visualize>true</visualize>
      <update_rate>50</update_rate>
      <ray>
         <scan>
            <horizontal>
               <samples>10</samples>
               <resolution>1</resolution> 
               <min_angle>-0.001</min_angle>
               <max_angle>0.001</max_angle>
            </horizontal>
            <vertical>
               <samples>10</samples>
               <resolution>1</resolution> 
               <min_angle>-0.001</min_angle>
               <max_angle>0.001</max_angle> 
            </vertical>
         </scan>
         <range>
            <min>0.01</min>
            <max>4</max>
            <resolution>0.02</resolution>
         </range>
      </ray>
      <plugin filename="libgazebo_ros_range.so" name="gazebo_ros_range">
         <gaussianNoise>0.005</gaussianNoise>
         <alwaysOn>true</alwaysOn>
         <updateRate>50</updateRate>
         <topicName>sonars/sonar2</topicName>
         <frameName>sonar2_link</frameName>
         <radiation>ULTRASOUND</radiation>
         <fov>0.2967</fov>
      </plugin>
   </sensor>  
   </gazebo>
   <gazebo reference="base_ir_front">        
   <sensor type="ray" name="TeraRanger">
      <pose>0 0 0 0 0 0</pose>
      <visualize>true</visualize>
      <update_rate>50</update_rate>
      <ray>
         <scan>
            <horizontal>
               <samples>10</samples>
               <resolution>1</resolution> 
               <min_angle>-0.14835</min_angle>
               <max_angle>0.14835</max_angle>
            </horizontal>
            <vertical>
               <samples>10</samples>
               <resolution>1</resolution> 
               <min_angle>-0.01</min_angle>
               <max_angle>0.01</max_angle> 
            </vertical>
         </scan>
         <range>
            <min>0.01</min>
            <max>2</max>
            <resolution>0.02</resolution>
         </range>
      </ray>
      <plugin filename="libgazebo_ros_range.so" name="gazebo_ros_range">
         <gaussianNoise>0.005</gaussianNoise>
         <alwaysOn>true</alwaysOn>
         <updateRate>50</updateRate>
         <topicName>sensor/ir_front</topicName>
         <frameName>base_ir_front</frameName>
         <radiation>INFRARED</radiation>
         <fov>0.2967</fov>
      </plugin>
   </sensor>  
   </gazebo>
  
  
  
  
  
  
  
  
  
  
  
  
  
  
  
</robot>
