<?xml version="1.0" encoding="utf-8"?>
<!-- This URDF was automatically created by SolidWorks to URDF Exporter! Originally created by Stephen Brawner (brawner@gmail.com) 
     Commit Version: 1.6.0-4-g7f85cfe  Build Version: 1.6.7995.38578
     For more information, please see http://wiki.ros.org/sw_urdf_exporter -->
<robot
  name="wheelchair_gp_description">
  <origin xyz="0 0 0.37687875"
        rpy="0 0 0" />
  <link
    name="base_link">
    <inertial>
      <!--origin
        xyz="-0.0393981982931111 -0.0192942548126665 -0.039140937433326"
        rpy="0 0 0" /-->
      
      
      <origin
        xyz="-0.0393981982931111 -0.0192942548126665 0.37687875"
        rpy="0 0 0" />
      <!--origin
        xyz="0.126687 -0.135590 0.376875"
        rpy="-0.000617 0.000934 -0.165792" /-->
      
      
      <mass
        value="102.779125185667" />
      <inertia
        ixx="2.42852161898811"
        ixy="0.00607091134061252"
        ixz="0.168870442034771"
        iyy="3.41666653629475"
        iyz="0.0626572771723994"
        izz="3.61718155630895" />
    </inertial>
    <visual>
      <origin
        xyz="0 0 0"
        rpy="0 0 0" />
      <geometry>
        <mesh
          filename="package://wheelchair_gp_description/meshes/base_link.STL" />
      </geometry>
      <material
        name="">
        <color
          rgba="0.647058823529412 0.619607843137255 0.588235294117647 1" />
      </material>
    </visual>
    <collision>
      <origin
        xyz="0 0 0"
        rpy="0 0 0" />
      <geometry>
        <mesh
          filename="package://wheelchair_gp_description/meshes/base_link.STL" />
      </geometry>
    </collision>
  </link>
  <link
    name="right_wheel_link">
    <inertial>
      <origin
        xyz="0.00522767894205917 -0.0300000000000016 -0.00855456468212881"
        rpy="0 0 0" />
      <mass
        value="3.63792559240615" />
      <inertia
        ixx="0.0501414836571904"
        ixy="2.71630419536481E-18"
        ixz="1.05138532973263E-06"
        iyy="0.0986432390550648"
        iyz="1.38840334310351E-16"
        izz="0.0501395483645078" />
    </inertial>
    <visual>
      <origin
        xyz="0 0 0"
        rpy="0 0 0" />
      <geometry>
        <mesh
          filename="package://wheelchair_gp_description/meshes/right_wheel_link.STL" />
      </geometry>
      <material
        name="">
        <color
          rgba="0.792156862745098 0.819607843137255 0.933333333333333 1" />
      </material>
    </visual>
    <collision>
      <origin
        xyz="0 0 0"
        rpy="0 0 0" />
      <geometry>
        <mesh
          filename="package://wheelchair_gp_description/meshes/right_wheel_link.STL" />
      </geometry>
    </collision>
  </link>
  <joint
    name="right_wheel_joint"
    type="continuous">
    <origin
      xyz="-0.0782370331711224 -0.291972990052419 -0.168374239027783"
      rpy="0 0 0" />
    <parent
      link="base_link" />
    <child
      link="right_wheel_link" />
    <axis
      xyz="0 1 0" />
    <dynamics
      friction="0.2" />
  </joint>
  <link
    name="left_wheel_link">
    <inertial>
      <origin
        xyz="0.000196414984617685 0.0300000000000019 -7.01814500629061E-05"
        rpy="0 0 0" />
      <mass
        value="3.63792559240615" />
      <inertia
        ixx="0.0501416166910778"
        ixy="-4.0426710917635E-18"
        ixz="-9.11182521543613E-07"
        iyy="0.0986432390550647"
        iyz="1.94384398447471E-16"
        izz="0.0501394153306204" />
    </inertial>
    <visual>
      <origin
        xyz="0 0 0"
        rpy="0 0 0" />
      <geometry>
        <mesh
          filename="package://wheelchair_gp_description/meshes/left_wheel_link.STL" />
      </geometry>
      <material
        name="">
        <color
          rgba="0.792156862745098 0.819607843137255 0.933333333333333 1" />
      </material>
    </visual>
    <collision>
      <origin
        xyz="0 0 0"
        rpy="0 0 0" />
      <geometry>
        <mesh
          filename="package://wheelchair_gp_description/meshes/left_wheel_link.STL" />
      </geometry>
    </collision>
  </link>
  <joint
    name="left_wheel_joint"
    type="continuous">
    <origin
      xyz="-0.0732001426526983 0.274956682906951 -0.177013089293031"
      rpy="0 0 0" />
    <parent
      link="base_link" />
    <child
      link="left_wheel_link" />
    <axis
      xyz="0 1 0" />
    <dynamics
      friction="0.2" />
  </joint>
  <link
    name="c_rr_link">
    <inertial>
      <origin
        xyz="-3.13828649178838E-08 -0.00433096505375735 0.0403769854454989"
        rpy="0 0 0" />
      <mass
        value="0.121211258399187" />
      <inertia
        ixx="0.000183879326955444"
        ixy="2.26483161972894E-11"
        ixz="-3.32770029958626E-12"
        iyy="0.000178527913603531"
        iyz="-2.16822895135042E-05"
        izz="2.37333780216088E-05" />
    </inertial>
    <visual>
      <origin
        xyz="0 0 0"
        rpy="0 0 0" />
      <geometry>
        <mesh
          filename="package://wheelchair_gp_description/meshes/c_rr_link.STL" />
      </geometry>
      <material
        name="">
        <color
          rgba="1 1 1 1" />
      </material>
    </visual>
    <collision>
      <origin
        xyz="0 0 0"
        rpy="0 0 0" />
      <geometry>
        <mesh
          filename="package://wheelchair_gp_description/meshes/c_rr_link.STL" />
      </geometry>
    </collision>
  </link>
  <joint
    name="c_rr_joint"
    type="fixed">
    <origin
      xyz="-0.34822491290783 -0.321068087348177 -0.277013089293035"
      rpy="0 0 0" />
    <parent
      link="base_link" />
    <child
      link="c_rr_link" />
    <axis
      xyz="0 0 1" />
  </joint>
  <link
    name="wheel_rr_link">
    <inertial>
      <origin
        xyz="0.00506493217230553 -0.033089156979335 0.00862243945121932"
        rpy="0 0 0" />
      <mass
        value="1.65462119171389" />
      <inertia
        ixx="0.00469812484295982"
        ixy="2.84758213931124E-10"
        ixz="-5.69706560197517E-19"
        iyy="0.00853457249449088"
        iyz="-1.67270638223886E-10"
        izz="0.00469812484295982" />
    </inertial>
    <visual>
      <origin
        xyz="0 0 0"
        rpy="0 0 0" />
      <geometry>
        <mesh
          filename="package://wheelchair_gp_description/meshes/wheel_rr_link.STL" />
      </geometry>
      <material
        name="">
        <color
          rgba="0.666666666666667 0.698039215686274 0.768627450980392 1" />
      </material>
    </visual>
    <collision>
      <origin
        xyz="0 0 0"
        rpy="0 0 0" />
      <geometry>
        <mesh
          filename="package://wheelchair_gp_description/meshes/wheel_rr_link.STL" />
      </geometry>
    </collision>
  </link>
  <joint
    name="wheel_rr_joint"
    type="continuous">
    <origin
      xyz="-0.00506493217230558 -0.026910843020665 -0.00862243945121771"
      rpy="0 0 0" />
    <parent
      link="c_rr_link" />
    <child
      link="wheel_rr_link" />
    <axis
      xyz="0 1 0" />
    <dynamics
      friction="0.01" />
  </joint>
  <link
    name="c_rl_link">
    <inertial>
      <origin
        xyz="3.13828648068615E-08 0.00433096505375724 0.0403769854454989"
        rpy="0 0 0" />
      <mass
        value="0.121211258399187" />
      <inertia
        ixx="0.000183879326955444"
        ixy="2.26483161862401E-11"
        ixz="3.32770036524469E-12"
        iyy="0.000178527913603531"
        iyz="2.16822895135046E-05"
        izz="2.37333780216089E-05" />
    </inertial>
    <visual>
      <origin
        xyz="0 0 0"
        rpy="0 0 0" />
      <geometry>
        <mesh
          filename="package://wheelchair_gp_description/meshes/c_rl_link.STL" />
      </geometry>
      <material
        name="">
        <color
          rgba="1 1 1 1" />
      </material>
    </visual>
    <collision>
      <origin
        xyz="0 0 0"
        rpy="0 0 0" />
      <geometry>
        <mesh
          filename="package://wheelchair_gp_description/meshes/c_rl_link.STL" />
      </geometry>
    </collision>
  </link>
  <joint
    name="c_rl_joint"
    type="fixed">
    <origin
      xyz="-0.341295239948457 0.30405178020271 -0.277013089293035"
      rpy="0 0 0" />
    <parent
      link="base_link" />
    <child
      link="c_rl_link" />
    <axis
      xyz="0 0 1" />
  </joint>
  <link
    name="wheel_rl_link">
    <inertial>
      <origin
        xyz="0.00909629415225127 0.0330891569793352 -0.00415420662650473"
        rpy="0 0 0" />
      <mass
        value="1.65462119171389" />
      <inertia
        ixx="0.00469812484295982"
        ixy="-1.37193706218052E-10"
        ixz="1.55689939042572E-19"
        iyy="0.00853457249449092"
        iyz="-3.00407360040444E-10"
        izz="0.00469812484295982" />
    </inertial>
    <visual>
      <origin
        xyz="0 0 0"
        rpy="0 0 0" />
      <geometry>
        <mesh
          filename="package://wheelchair_gp_description/meshes/wheel_rl_link.STL" />
      </geometry>
      <material
        name="">
        <color
          rgba="0.666666666666667 0.698039215686274 0.768627450980392 1" />
      </material>
    </visual>
    <collision>
      <origin
        xyz="0 0 0"
        rpy="0 0 0" />
      <geometry>
        <mesh
          filename="package://wheelchair_gp_description/meshes/wheel_rl_link.STL" />
      </geometry>
    </collision>
  </link>
  <joint
    name="wheel_rl_joint"
    type="continuous">
    <origin
      xyz="-0.0090962941522516 0.0269108430206658 0.00415420662650628"
      rpy="0 0 0" />
    <parent
      link="c_rl_link" />
    <child
      link="wheel_rl_link" />
    <axis
      xyz="0 1 0" />
    <dynamics
      friction="0.01" />
  </joint>
  <link
    name="c_fl_link">
    <inertial>
      <origin
        xyz="3.13828648068615E-08 0.00433096505375724 0.0403769854454989"
        rpy="0 0 0" />
      <mass
        value="0.121211258399187" />
      <inertia
        ixx="0.000183879326955444"
        ixy="2.26483161950023E-11"
        ixz="3.32770038433127E-12"
        iyy="0.000178527913603531"
        iyz="2.16822895135046E-05"
        izz="2.37333780216089E-05" />
    </inertial>
    <visual>
      <origin
        xyz="0 0 0"
        rpy="0 0 0" />
      <geometry>
        <mesh
          filename="package://wheelchair_gp_description/meshes/c_fl_link.STL" />
      </geometry>
      <material
        name="">
        <color
          rgba="1 1 1 1" />
      </material>
    </visual>
    <collision>
      <origin
        xyz="0 0 0"
        rpy="0 0 0" />
      <geometry>
        <mesh
          filename="package://wheelchair_gp_description/meshes/c_fl_link.STL" />
      </geometry>
    </collision>
  </link>
  <joint
    name="c_fl_joint"
    type="fixed">
    <origin
      xyz="0.27689495464306 0.30405178020271 -0.277013089293036"
      rpy="0 0 0" />
    <parent
      link="base_link" />
    <child
      link="c_fl_link" />
    <axis
      xyz="0 0 1" />
  </joint>
  <link
    name="wheel_fl_link">
    <inertial>
      <origin
        xyz="0.00446139900539383 0.0330891569793352 -0.00894963233404822"
        rpy="0 0 0" />
      <mass
        value="1.65462119171388" />
      <inertia
        ixx="0.00469812484295979"
        ixy="-2.95563822410245E-10"
        ixz="2.01399739995211E-18"
        iyy="0.00853457249449084"
        iyz="-1.47338792133348E-10"
        izz="0.00469812484295979" />
    </inertial>
    <visual>
      <origin
        xyz="0 0 0"
        rpy="0 0 0" />
      <geometry>
        <mesh
          filename="package://wheelchair_gp_description/meshes/wheel_fl_link.STL" />
      </geometry>
      <material
        name="">
        <color
          rgba="0.666666666666667 0.698039215686274 0.768627450980392 1" />
      </material>
    </visual>
    <collision>
      <origin
        xyz="0 0 0"
        rpy="0 0 0" />
      <geometry>
        <mesh
          filename="package://wheelchair_gp_description/meshes/wheel_fl_link.STL" />
      </geometry>
    </collision>
  </link>
  <joint
    name="wheel_fl_joint"
    type="continuous">
    <origin
      xyz="-0.00446139900539422 0.0269108430206658 0.00894963233404933"
      rpy="0 0 0" />
    <parent
      link="c_fl_link" />
    <child
      link="wheel_fl_link" />
    <axis
      xyz="0 -1 0" />
    <dynamics
      friction="0.01" />
  </joint>
  <link
    name="c_fr_link">
    <inertial>
      <origin
        xyz="-3.13828649178838E-08 -0.00433096505375735 0.0403769854454989"
        rpy="0 0 0" />
      <mass
        value="0.121211258399187" />
      <inertia
        ixx="0.000183879326955444"
        ixy="2.26483162485928E-11"
        ixz="-3.32769997596411E-12"
        iyy="0.000178527913603531"
        iyz="-2.16822895135042E-05"
        izz="2.37333780216088E-05" />
    </inertial>
    <visual>
      <origin
        xyz="0 0 0"
        rpy="0 0 0" />
      <geometry>
        <mesh
          filename="package://wheelchair_gp_description/meshes/c_fr_link.STL" />
      </geometry>
      <material
        name="">
        <color
          rgba="1 1 1 1" />
      </material>
    </visual>
    <collision>
      <origin
        xyz="0 0 0"
        rpy="0 0 0" />
      <geometry>
        <mesh
          filename="package://wheelchair_gp_description/meshes/c_fr_link.STL" />
      </geometry>
    </collision>
  </link>
  <joint
    name="c_fr_joint"
    type="fixed">
    <origin
      xyz="0.283824627602434 -0.321068087348177 -0.277013089293038"
      rpy="0 0 0" />
    <parent
      link="base_link" />
    <child
      link="c_fr_link" />
    <axis
      xyz="0 0 1" />
  </joint>
  <link
    name="wheel_fr_link">
    <inertial>
      <origin
        xyz="5.55111512312578E-17 -0.05 1.11022302462516E-16"
        rpy="0 0 0" />
      <mass
        value="1.65462119171389" />
      <inertia
        ixx="0.00469812484295983"
        ixy="-2.5288319359234E-10"
        ixz="1.93364761434344E-18"
        iyy="0.00853457249449091"
        iyz="-2.12407128112193E-10"
        izz="0.00469812484295983" />
    </inertial>
    <visual>
      <origin
        xyz="0 0 0"
        rpy="0 0 0" />
      <geometry>
        <mesh
          filename="package://wheelchair_gp_description/meshes/wheel_fr_link.STL" />
      </geometry>
      <material
        name="">
        <color
          rgba="0.666666666666667 0.698039215686274 0.768627450980392 1" />
      </material>
    </visual>
    <collision>
      <origin
        xyz="0 0 0"
        rpy="0 0 0" />
      <geometry>
        <mesh
          filename="package://wheelchair_gp_description/meshes/wheel_fr_link.STL" />
      </geometry>
    </collision>
  </link>
  <joint
    name="wheel_fr_joint"
    type="continuous">
    <origin
      xyz="0 -0.01 0"
      rpy="0 0 0" />
    <parent
      link="c_fr_link" />
    <child
      link="wheel_fr_link" />
    <axis
      xyz="0 1 0" />
    <dynamics
      friction="0.01" />
  </joint>
  <link
    name="chair_link">
    <inertial>
      <origin
        xyz="-0.186634259898291 0.000154601290753766 0.685315360247557"
        rpy="0 0 0" />
      <mass
        value="114.06700966343" />
      <inertia
        ixx="9.01362340563565"
        ixy="0.0220781525155631"
        ixz="2.75872047758239"
        iyy="10.1495034165686"
        iyz="0.0794043830621218"
        izz="6.74522524259257" />
    </inertial>
    <visual>
      <origin
        xyz="0 0 0"
        rpy="0 0 0" />
      <geometry>
        <mesh
          filename="package://wheelchair_gp_description/meshes/chair_link.STL" />
      </geometry>
      <material
        name="">
        <color
          rgba="1 1 1 0.3" />
      </material>
    </visual>
    <collision>
      <origin
        xyz="0 0 0"
        rpy="0 0 0" />
      <geometry>
        <mesh
          filename="package://wheelchair_gp_description/meshes/chair_link.STL" />
      </geometry>
    </collision>
  </link>
  <joint
    name="chair_joint"
    type="fixed">
    <origin
      xyz="0.0850649844123319 -0.0219729900524205 -0.213013089293032"
      rpy="0 0 0" />
    <parent
      link="base_link" />
    <child
      link="chair_link" />
    <axis
      xyz="0 0 0" />
  </joint>
  <link
    name="laser_link">
    <inertial>
      <origin
        xyz="0.000495122459176101 0.0164439641378342 0.00393830970343445"
        rpy="0 0 0" />
      <mass
        value="0.171593009361433" />
      <inertia
        ixx="8.81695539048464E-05"
        ixy="1.02435205100894E-06"
        ixz="-2.45142607227698E-07"
        iyy="5.55321136136403E-05"
        iyz="-4.34621326843885E-06"
        izz="0.000129552246180809" />
    </inertial>
    <visual>
      <origin
        xyz="0 0 0"
        rpy="0 0 0" />
      <geometry>
        <mesh
          filename="package://wheelchair_gp_description/meshes/laser_link.STL" />
      </geometry>
      <material
        name="">
        <color
          rgba="1 1 1 0.3" />
      </material>
    </visual>
    <collision>
      <origin
        xyz="0 0 0"
        rpy="0 0 0" />
      <geometry>
        <mesh
          filename="package://wheelchair_gp_description/meshes/laser_link.STL" />
      </geometry>
    </collision>
  </link>
  <joint
    name="laser_joint"
    type="fixed">
    <origin
      xyz="-0.374765127065032 0 1.62499193284082"
      rpy="0 0 0" />
    <parent
      link="chair_link" />
    <child
      link="laser_link" />
    <axis
      xyz="0 0 0" />
  </joint>
  <link
    name="imu_link">
    <inertial>
      <origin
        xyz="0.0189494667461579 0.005 -0.0105210784313726"
        rpy="0 0 0" />
      <mass
        value="0.00813424809545575" />
      <inertia
        ixx="3.67920423318068E-07"
        ixy="-1.26706175703357E-21"
        ixz="1.24717459690727E-21"
        iyy="1.27375650027243E-06"
        iyz="-2.11757715652617E-22"
        izz="1.04140687854529E-06" />
    </inertial>
    <visual>
      <origin
        xyz="0 0 0"
        rpy="0 0 0" />
      <geometry>
        <mesh
          filename="package://wheelchair_gp_description/meshes/imu_link.STL" />
      </geometry>
      <material
        name="">
        <color
          rgba="1 1 1 1" />
      </material>
    </visual>
    <collision>
      <origin
        xyz="0 0 0"
        rpy="0 0 0" />
      <geometry>
        <mesh
          filename="package://wheelchair_gp_description/meshes/imu_link.STL" />
      </geometry>
    </collision>
  </link>
  <joint
    name="imu_joint"
    type="fixed">
    <origin
      xyz="0.156900923854985 0.0739145260442063 0.136986910706968"
      rpy="1.5707963267949 0 0" />
    <parent
      link="base_link" />
    <child
      link="imu_link" />
    <axis
      xyz="0 0 0" />
  </joint>
  
    

   <gazebo reference="imu_link">
    <gravity>true</gravity>
    <sensor name="imu_sensor" type="imu">
      <always_on>true</always_on>
      <update_rate>100</update_rate>
      <visualize>true</visualize>
      <topic>__default_topic__</topic>
      <plugin filename="libgazebo_ros_imu_sensor.so" name="imu_plugin">
        <topicName>imu</topicName>
        <bodyName>imu_link</bodyName>
        <updateRateHZ>10.0</updateRateHZ>
        <gaussianNoise>0.0</gaussianNoise>
        <xyzOffset>0 0 0</xyzOffset>
        <rpyOffset>0 0 0</rpyOffset>
        <frameName>imu_link</frameName>
        <initialOrientationAsReference>false</initialOrientationAsReference>
      </plugin>
      <pose>0 0 0 0 0 0</pose>
    </sensor>
  </gazebo>
  
  
  
  

<gazebo reference="right_wheel_link">
<material>Gazebo/Black</material>
</gazebo>	

<gazebo reference="left_wheel_link">

<material>Gazebo/Black</material>
</gazebo>

<gazebo reference="wheel_rl_link">

<material>Gazebo/Blue</material>
</gazebo>	

<gazebo reference="wheel_rr_link">

<material>Gazebo/Blue</material>
</gazebo>



<gazebo reference="wheel_fr_link">

<material>Gazebo/Blue</material>
</gazebo>	

<gazebo reference="wheel_fl_link">

<material>Gazebo/Blue</material>
</gazebo>



<gazebo reference="base_link">

<material>Gazebo/Silver</material>
</gazebo>



<gazebo reference="chair_link">

<material>Gazebo/Red</material>
</gazebo>



<gazebo reference="laser_link">

<material>Gazebo/Green</material>
</gazebo>
  <!-- hokuyo -->
  <gazebo reference="laser_link">
    <sensor type="ray" name="head_hokuyo_sensor">
      <pose>0 0 0 0 0 0</pose>
      <visualize>true</visualize>
      <update_rate>40</update_rate>
      <ray>
        <scan>
          <horizontal>
            <samples>1024</samples>
            <resolution>1</resolution>
            <min_angle>-3.14</min_angle>
            <max_angle>3.14</max_angle>
          </horizontal>
        </scan>
        <range>
          <min>0.10</min>
          <max>30.0</max>
          <resolution>0.01</resolution>
        </range>
        <noise>
          <type>gaussian</type>
          <!-- Noise parameters based on published spec for Hokuyo laser
               achieving "+-30mm" accuracy at range < 10m.  A mean of 0.0m and
               stddev of 0.01m will put 99.7% of samples within 0.03m of the true
               reading. -->
          <mean>0.0</mean>
          <stddev>0.01</stddev>
        </noise>
      </ray>
      <plugin name="gazebo_ros_head_hokuyo_controller" filename="libgazebo_ros_laser.so">
        <topicName>/scan</topicName>
        <frameName>laser_link</frameName>
      </plugin>
    </sensor>
  </gazebo>

  
  

  
  <gazebo>
  <plugin name="differential_drive_controller" filename="libgazebo_ros_diff_drive.so">
    <alwaysOn>true</alwaysOn>
    <legacyMode>false</legacyMode>
    <updateRate>40</updateRate>
    <leftJoint>left_wheel_joint</leftJoint>
    <rightJoint>right_wheel_joint</rightJoint>
    <wheelSeparation>0.6</wheelSeparation>
    <wheelDiameter>0.3</wheelDiameter>
    <torque>250</torque>
    <wheelTorque>500</wheelTorque>
    <commandTopic>cmd_vel</commandTopic>
    <odometryTopic>odom</odometryTopic>
    <odometryFrame>odom</odometryFrame>
    <robotBaseFrame>base_link</robotBaseFrame>
  </plugin>
</gazebo>



  
  
  
  
  
  
  
  
  
  
  
  
  
</robot>
